Workbook

Sheet Summary Dashboard
A1: Mira AWS Cost Analysis - Summary Dashboard
A2: Model: OpenAI GPT-OSS-20B on Amazon Bedrock | C2: COST: $0.000030/1000 input tokens
A4: Current Monthly Costs (Base Infrastructure)
A5: Category | B5: Service | C5: Monthly Cost ($) | D5: Notes
A6: VPC Networking | B6: Interface Endpoints (6×2 AZs) | C6: ='Fixed Costs'!D12 -> 87.7 | D6: Bedrock, SecretsManager, CloudWatch, STS, X-Ray, EventBridge
A7: VPC Networking | B7: NAT Gateways (2) | C7: ='Fixed Costs'!D15 -> 65.7 | D7: $0.045/hr each
A8: VPC Networking | B8: Public IPv4 Addresses (2) | C8: ='Fixed Costs'!D18 -> 7.3 | D8: $0.005/hr each
A9: VPC Networking | B9: Gateway Endpoints (S3, DynamoDB) | C9: ='Fixed Costs'!D21 -> 0 | D9: Free
A10: Compute | B10: Lambda (base) | C10: ='Fixed Costs'!D24 -> 1 | D10: Free tier covers most
A11: Monitoring | B11: CloudWatch & X-Ray | C11: ='Fixed Costs'!D27 -> 5 | D11: Minimal usage
A12: Security | B12: Secrets Manager | C12: ='Fixed Costs'!D30 -> 0.4 | D12: $0.40/secret/month
A13: DevOps | B13: Terraform State (S3) | C13: ='Fixed Costs'!D33 -> 0.023 | D13: Minimal storage
A15: Total Fixed Infrastructure Cost: | C15: =SUM(C6:C13) -> 167.123
A17: Variable Costs (for 100 users)
A18: Bedrock GPT-OSS-20B | C18: ='Variable Costs'!D25 -> 1.27
A19: API Gateway + Lambda + DynamoDB | C19: ='Variable Costs'!D29+'Variable Costs'!D41+'Variable Costs'!D48 -> 0.045
A20: Other variable costs | C20: ='Variable Costs'!D53+'Variable Costs'!D63 -> 1.075
A22: TOTAL FOR 100 USERS: | C22: =C15+'Variable Costs'!D65 -> 169.513
A23: APPROX. TOTAL FOR 1 USER: | C23: =(C15+'Variable Costs'!D65)/100 -> 1.69513

Sheet Fixed Costs
A1: Fixed Infrastructure Costs (Monthly)
A3: VPC INTERFACE ENDPOINTS
A4: Item | B4: Unit Price | C4: Quantity | D4: Monthly Cost ($)
A5: Hourly rate per endpoint per AZ | B5: 0.01
A6: Hours per month | B6: 730
A7: Number of interface endpoints | B7: 6 | D7: Bedrock, Secrets Manager, CloudWatch Logs, STS, X-Ray, EventBridge
A8: Number of Availability Zones | B8: 2
A10: Monthly cost per endpoint | D10: =B5*B6 -> 7.3
A11: Data processing (est. GB) | B11: 10 | C11: 0.01 | D11: =B11*C11 -> 0.1
A12: TOTAL INTERFACE ENDPOINTS | D12: =(D10*B7*B8)+D11 -> 87.7
A14: NAT GATEWAYS
A15: NAT Gateway hourly rate | B15: 0.045 | C15: 2 | D15: =B15*B6*C15 -> 65.7
A17: PUBLIC IPv4 ADDRESSES
A18: IPv4 hourly rate | B18: 0.005 | C18: 2 | D18: =B18*B6*C18 -> 7.3
A20: GATEWAY ENDPOINTS
A21: S3 & DynamoDB Gateway Endpoints | D21: 0 | E21: FREE
A23: LAMBDA (BASE)
A24: EventBridge keep-warm (minimal) | D24: 1
A26: MONITORING
A27: CloudWatch & X-Ray (estimated) | D27: 5
A29: SECRETS MANAGER
A30: Number of secrets | B30: 1 | C30: 0.4 | D30: =B30*C30 -> 0.4
A32: S3 STORAGE
A33: Terraform state & artifacts (GB) | B33: 1 | C33: 0.023 | D33: =B33*C33 -> 0.023
A35: TOTAL FIXED MONTHLY COSTS | D35: =D12+D15+D18+D21+D24+D27+D30+D33 -> 167.123

Sheet Variable Costs
A1: Variable Costs (Scales with Usage)
A3: USER ASSUMPTIONS
A4: Number of users | B4: 100
A5: Conversations per user/month | B5: 20
A6: Messages per conversation | B6: 10
A7: User messages per conversation | C7: =B6/2 -> 5
A8: AI responses per conversation | C8: =B6/2 -> 5
A10: TOKEN ASSUMPTIONS
A11: Avg input tokens per message | B11: 500
A12: Avg output tokens per response | B12: 800
A14: CALCULATED USAGE
A15: Total API requests/month | C15: =B4*B5*B6 -> 20000
A16: Total input tokens/month | C16: =B4*B5*C7*B11 -> 5000000
A17: Total output tokens/month | C17: =B4*B5*C8*B12 -> 8000000
A19: SERVICE COSTS
A20: AMAZON BEDROCK (OpenAI GPT-OSS-20B)
A21: Input token price (per 1K) | B21: 3e-05 | D21: ~100x cheaper than Claude 3.5 Sonnet!
A22: Output token price (per 1K) | B22: 0.00014
A23: Input token cost | D23: =(C16/1000)*B21 -> 0.15
A24: Output token cost | D24: =(C17/1000)*B22 -> 1.12
A25: Total Bedrock cost | D25: =D23+D24 -> 1.27
A27: API GATEWAY (HTTP API)
A28: Price per million requests | B28: 1
A29: Total API Gateway cost | D29: =(C15/1000000)*B28 -> 0.02
A31: LAMBDA
A32: Memory (MB) | B32: 1024
A33: Avg duration (seconds) | B33: 3
A34: GB-seconds used | C34: =C15*B33*(B32/1024) -> 60000
A35: Free tier GB-seconds | B35: 400000
A36: Billable GB-seconds | C36: =MAX(0,C34-B35) -> 0
A37: Price per GB-second | B37: 1.66667e-05
A38: Lambda compute cost | D38: =C36*B37 -> 0
A39: Lambda requests (after 1M free) | C39: =MAX(0,C15-1000000) -> 0
A40: Lambda request cost ($0.20/million) | D40: =(C39/1000000)*0.2 -> 0
A41: Total Lambda cost | D41: =D38+D40 -> 0
A43: DYNAMODB (On-Demand)
A44: Write requests (per user/month) | B44: 100
A45: Read requests (per user/month) | B45: 500
A46: Write price per million | B46: 1.25
A47: Read price per million | B47: 0.25
...

Sheet Scaling Scenarios
A1: Cost Scaling Scenarios (GPT-OSS-20B)
A2: Note: GPT-OSS-20B is ~100x cheaper than Claude, making AI costs nearly negligible!
A4: Users | B4: Fixed Costs | C4: Variable Costs | D4: Total Monthly | E4: Cost per User | F4: Notes
A5: 10 | B5: ='Fixed Costs'!D35 -> 167.123 | C5: ='Variable Costs'!D65*(A5/100) -> 0.239 | D5: =B5+C5 -> 167.362 | E5: =D5/A5 -> 16.7362 | F5: Dev/test scenario
A6: 50 | B6: ='Fixed Costs'!D35 -> 167.123 | C6: ='Variable Costs'!D65*(A6/100) -> 1.195 | D6: =B6+C6 -> 168.318 | E6: =D6/A6 -> 3.36636 | F6: Small pilot
A7: 100 | B7: ='Fixed Costs'!D35 -> 167.123 | C7: ='Variable Costs'!D65*(A7/100) -> 2.39 | D7: =B7+C7 -> 169.513 | E7: =D7/A7 -> 1.69513 | F7: Initial launch
A8: 250 | B8: ='Fixed Costs'!D35 -> 167.123 | C8: ='Variable Costs'!D65*(A8/100) -> 5.975 | D8: =B8+C8 -> 173.098 | E8: =D8/A8 -> 0.692392 | F8: Growing user base
A9: 500 | B9: ='Fixed Costs'!D35 -> 167.123 | C9: ='Variable Costs'!D65*(A9/100) -> 11.95 | D9: =B9+C9 -> 179.073 | E9: =D9/A9 -> 0.358146 | F9: Mid-scale production
A10: 1000 | B10: ='Fixed Costs'!D35 -> 167.123 | C10: ='Variable Costs'!D65*(A10/100) -> 23.9 | D10: =B10+C10 -> 191.023 | E10: =D10/A10 -> 0.191023 | F10: Full scale
A13: KEY INSIGHTS:
A14: 1. Fixed infrastructure costs (~$168/month) dominate your bill at low user counts
A15: 2. GPT-OSS-20B costs are nearly ZERO (~$0.97 for 100 users vs ~$135 for Claude)
A16: 3. Your main cost optimization opportunity is VPC infrastructure, NOT the AI model
A17: 4. At 1000 users, total cost is still under $200/month - extremely cost-effective!

Sheet Amazon Q Comparison
A1: Amazon Q Estimate vs. Verified Analysis
A3: AMAZON Q ESTIMATES
A4: November 2025 Total: | B4: 54.92
A5: VPC (58%): | B5: 31.87
A6: EC2-Other (41.5%): | B6: 22.82
A7: Other services (<1%): | B7: 0.24
A9: December Projection: | B9: 145.62
A11: 100 User Estimate (Amazon Q):
A12: - Best case: | B12: 1456
A13: - Worst case: | B13: 14562
A14: - "Realistic": | B14: 2000-4000
A16: VERIFIED ANALYSIS (GPT-OSS-20B)
A17: Expected Fixed Infrastructure: | B17: ='Fixed Costs'!D35 -> 167.123 | C17: Based on architecture diagram
A18: 100 User Variable Costs: | B18: ='Variable Costs'!D65 -> 2.39 | C18: GPT-OSS-20B is ~100x cheaper than Claude!
A19: TOTAL for 100 Users: | B19: =B17+B18 -> 169.513 | C19: ~10-20x LOWER than Amazon Q's estimate!
A21: MODEL COST COMPARISON
A22: GPT-OSS-20B (your model): | B22: ='Variable Costs'!D25 -> 1.27 | C22: $0.03/1M input, $0.14/1M output
A23: Claude 3.5 Sonnet (comparison): | B23: =('Variable Costs'!C16/1000)*0.003+('Variable Costs'!C17/1000)*0.015 -> 135 | C23: $3/1M input, $15/1M output
A24: SAVINGS by using GPT-OSS-20B: | B24: =B23-B22 -> 133.73 | C24: per month for 100 users
A26: DISCREPANCIES WITH AMAZON Q
A27: 1. Amazon Q didn't account for GPT-OSS-20B's extremely low pricing
A28: 2. Amazon Q assumed 'linear scaling' - WRONG for serverless architecture
A29: 3. VPC/NAT costs are FIXED, not per-user variable costs
A30: 4. Amazon Q's '100 user estimate' of $2,000-4,000 is ~10-20x too high!
A31: 5. Your biggest cost driver is VPC infrastructure, NOT the AI model
A32: 6. December trend ($145.62) suggests partial deployment, not full infra
A34: RECOMMENDATIONS
A35: • Consider reducing VPC endpoints (use NAT for low-traffic services)
A36: • Single NAT Gateway for dev environment saves ~$33/month
A37: • Your AI model choice (GPT-OSS-20B) is already optimal for cost
A38: • Focus optimization efforts on VPC infrastructure, not Bedrock
A39: • At current model pricing, you can easily scale to 1000+ users
